<?xml version="1.0"?>

<robot name="gen3_arm" xmlns:xacro="http://ros.org/wiki/xacro">

  <!-- Propagate last link name information because it is the gripper's parent link -->
  <xacro:property name="last_arm_link" value="end_effector_link"/>

  <xacro:macro name="load_arm" params="parent:='' dof vision prefix *origin">
    <link name="${prefix}base_link">
      <inertial>
        <origin xyz="-0.000648 -0.000166 0.084487" rpy="0 0 0" />
        <mass value="1.697" />
        <inertia ixx="0.004622" ixy="9E-06" ixz="6E-05" iyy="0.004495" iyz="9E-06" izz="0.002079" />
      </inertial>
      <visual>
        <origin xyz="0 0 0" rpy="0 0 0" />
        <geometry>
          <mesh filename="package://kortex_description/arms/gen3/${dof}dof/meshes/base_link.STL" />
        </geometry>
        <material name="">
          <color rgba="0.75294 0.75294 0.75294 1" />
        </material>
      </visual>
      <collision>
        <origin xyz="0 0 0" rpy="0 0 0" />
        <geometry>
          <mesh filename="package://kortex_description/arms/gen3/${dof}dof/meshes/base_link.STL" />
        </geometry>
      </collision>
    </link>
    <link name="${prefix}shoulder_link">
      <inertial>
        <origin xyz="-2.3E-05 -0.010364 -0.07336" rpy="0 0 0" />
        <mass value="1.377" />
        <inertia ixx="0.00457" ixy="1E-06" ixz="2E-06" iyy="0.004831" iyz="0.000448" izz="0.001409" />
      </inertial>
      <visual>
        <origin xyz="0 0 0" rpy="0 0 0" />
        <geometry>
          <mesh filename="package://kortex_description/arms/gen3/${dof}dof/meshes/shoulder_link.STL" />
        </geometry>
        <material name="">
          <color rgba="0.75294 0.75294 0.75294 1" />
        </material>
      </visual>
      <collision>
        <origin xyz="0 0 0" rpy="0 0 0" />
        <geometry>
          <mesh filename="package://kortex_description/arms/gen3/${dof}dof/meshes/shoulder_link.STL" />
        </geometry>
      </collision>
    </link>
    <joint name="${prefix}joint_1" type="continuous">
      <origin xyz="0 0 0.15643" rpy="-3.1416 0.0 0.0" />
      <parent link="${prefix}base_link" />
      <child link="${prefix}shoulder_link" />
      <axis xyz="0 0 1" />
      <limit effort="39" velocity="1.3963" />
    </joint>
    <link name="${prefix}bicep_link">
      <inertial>
        <origin xyz="3.5E-05 -0.208207 -0.01889" rpy="0 0 0" />
        <mass value="1.262" />
        <inertia ixx="0.046752" ixy="-9E-06" ixz="0" iyy="0.00085" iyz="-9.8E-05" izz="0.047188" />
      </inertial>
      <visual>
        <origin xyz="0 0 0" rpy="0 0 0" />
        <geometry>
          <mesh filename="package://kortex_description/arms/gen3/${dof}dof/meshes/bicep_link.STL" />
        </geometry>
        <material name="">
          <color rgba="0.75294 0.75294 0.75294 1" />
        </material>
      </visual>
      <collision>
        <origin xyz="0 0 0" rpy="0 0 0" />
        <geometry>
          <mesh filename="package://kortex_description/arms/gen3/${dof}dof/meshes/bicep_link.STL" />
        </geometry>
      </collision>
    </link>
    <joint name="${prefix}joint_2" type="revolute">
      <origin xyz="0 0.005375 -0.12838" rpy="1.5708 0.0 0.0" />
      <parent link="${prefix}shoulder_link" />
      <child link="${prefix}bicep_link" />
      <axis xyz="0 0 1" />
      <limit lower="-2.24" upper="2.24" effort="39" velocity="1.3963" />
    </joint>
    <link name="${prefix}forearm_link">
      <inertial>
        <origin xyz="1.8E-05 0.076168 -0.01397" rpy="0 0 0" />
        <mass value="0.93" />
        <inertia ixx="0.008292" ixy="-1E-06" ixz="0" iyy="0.000628" iyz="0.000432" izz="0.008464" />
      </inertial>
      <visual>
        <origin xyz="0 0 0" rpy="0 0 0" />
        <geometry>
          <mesh filename="package://kortex_description/arms/gen3/${dof}dof/meshes/forearm_link.STL" />
        </geometry>
        <material name="">
          <color rgba="0.75294 0.75294 0.75294 1" />
        </material>
      </visual>
      <collision>
        <origin xyz="0 0 0" rpy="0 0 0" />
        <geometry>
          <mesh filename="package://kortex_description/arms/gen3/${dof}dof/meshes/forearm_link.STL" />
        </geometry>
      </collision>
    </link>
    <joint name="${prefix}joint_3" type="revolute">
      <origin xyz="0 -0.41 0" rpy="3.1416 0 0" />
      <parent link="${prefix}bicep_link" />
      <child link="${prefix}forearm_link" />
      <axis xyz="0 0 1" />
      <limit lower="-2.57" upper="2.57" effort="39" velocity="1.3963" />
    </joint>
    <link name="${prefix}spherical_wrist_1_link">
      <inertial>
        <origin xyz="-1E-06 0.008486 -0.062937" rpy="0 0 0" />
        <mass value="0.6781" />
        <inertia ixx="0.001645" ixy="0" ixz="0" iyy="0.001666" iyz="-0.000234" izz="0.000389" />
      </inertial>
      <visual>
        <origin xyz="0 0 0" rpy="0 0 0" />
        <geometry>
          <mesh filename="package://kortex_description/arms/gen3/${dof}dof/meshes/spherical_wrist_1_link.STL" />
        </geometry>
        <material name="">
          <color rgba="0.75294 0.75294 0.75294 1" />
        </material>
      </visual>
      <collision>
        <origin xyz="0 0 0" rpy="0 0 0" />
        <geometry>
          <mesh filename="package://kortex_description/arms/gen3/${dof}dof/meshes/spherical_wrist_1_link.STL" />
        </geometry>
      </collision>
    </link>
    <joint name="${prefix}joint_4" type="continuous">
      <origin xyz="0 0.20843 -0.006375" rpy="1.5708 0.0 0.0" />
      <parent link="${prefix}forearm_link" />
      <child link="${prefix}spherical_wrist_1_link" />
      <axis xyz="0 0 1" />
      <limit effort="9" velocity="1.2218" />
    </joint>
    <link name="${prefix}spherical_wrist_2_link">
      <inertial>
        <origin xyz="-1E-06 0.046429 -0.008704" rpy="0 0 0" />
        <mass value="0.678" />
        <inertia ixx="0.001685" ixy="0" ixz="0" iyy="0.0004" iyz="0.000255" izz="0.001696" />
      </inertial>
      <visual>
        <origin xyz="0 0 0" rpy="0 0 0" />
        <geometry>
          <mesh filename="package://kortex_description/arms/gen3/${dof}dof/meshes/spherical_wrist_2_link.STL" />
        </geometry>
        <material name="">
          <color rgba="0.75294 0.75294 0.75294 1" />
        </material>
      </visual>
      <collision>
        <origin xyz="0 0 0" rpy="0 0 0" />
        <geometry>
          <mesh filename="package://kortex_description/arms/gen3/${dof}dof/meshes/spherical_wrist_2_link.STL" />
        </geometry>
      </collision>
    </link>
    <joint name="${prefix}joint_5" type="revolute">
      <origin xyz="0 -0.00017505 -0.10593" rpy="-1.5708 0.0 0.0" />
      <parent link="${prefix}spherical_wrist_1_link" />
      <child link="${prefix}spherical_wrist_2_link" />
      <axis xyz="0 0 1" />
      <limit lower="-2.09" upper="2.09" effort="9" velocity="1.2218" />
    </joint>
    <xacro:if value="${vision}">
    <link name="${prefix}bracelet_link">
      <inertial>
        <origin xyz="0.000281 0.011402 -0.029798" rpy="0 0 0" />
        <mass value="0.5" />
        <inertia ixx="0.000587" ixy="3E-06" ixz="3E-06" iyy="0.000369" iyz="-0.000118" izz="0.000609" />
      </inertial>
      <visual>
        <origin xyz="0 0 0" rpy="0 0 0" />
        <geometry>
          <mesh filename="package://kortex_description/arms/gen3/${dof}dof/meshes/bracelet_with_vision_link.STL" />
        </geometry>
        <material name="">
          <color rgba="0.75294 0.75294 0.75294 1" />
        </material>
      </visual>
      <collision>
        <origin xyz="0 0 0" rpy="0 0 0" />
        <geometry>
          <mesh filename="package://kortex_description/arms/gen3/${dof}dof/meshes/bracelet_with_vision_link.STL" />
        </geometry>
      </collision>
    </link>
    </xacro:if>
    <xacro:unless value="${vision}">
    <link name="${prefix}bracelet_link">
      <inertial>
        <origin xyz="-9.3E-05 0.000132 -0.022905" rpy="0 0 0" />
        <mass value="0.364" />
        <inertia ixx="0.000214" ixy="0" ixz="1E-06" iyy="0.000223" iyz="-2E-06" izz="0.00024" />
      </inertial>
      <visual>
        <origin xyz="0 0 0" rpy="0 0 0" />
        <geometry>
          <mesh filename="package://kortex_description/arms/gen3/${dof}dof/meshes/bracelet_no_vision_link.STL" />
        </geometry>
        <material name="">
          <color rgba="0.75294 0.75294 0.75294 1" />
        </material>
      </visual>
      <collision>
        <origin xyz="0 0 0" rpy="0 0 0" />
        <geometry>
          <mesh filename="package://kortex_description/arms/gen3/${dof}dof/meshes/bracelet_no_vision_link.STL" />
        </geometry>
      </collision>
    </link>
    </xacro:unless>
    <joint name="${prefix}joint_6" type="continuous">
      <origin xyz="0 0.10593 -0.00017505" rpy="1.5708 0.0 0.0" />
      <parent link="${prefix}spherical_wrist_2_link" />
      <child link="${prefix}bracelet_link" />
      <axis xyz="0 0 1" />
      <limit effort="9" velocity="1.2218" />
    </joint>
    <link name="${prefix}end_effector_link" />
    <joint
      name="${prefix}end_effector"
      type="fixed">
      <origin xyz="0 0 -0.0615250000000001" rpy="3.14159265358979 1.09937075168372E-32 3.14159265358979" />
      <parent
        link="${prefix}bracelet_link" />
      <child
        link="${prefix}end_effector_link" />
      <axis
        xyz="0 0 0" />
    </joint>
    <xacro:if value="${vision}">
      <link name="${prefix}camera_link" />
      <joint name="${prefix}camera_module" type="fixed">
        <origin xyz="0 0.05639 -0.00305" rpy="3.14159265358979 3.14159265358979 0" />
        <parent link="${prefix}end_effector_link" />
        <child  link="${prefix}camera_link" />
      </joint>
      <link name="${prefix}camera_depth_frame" />
      <joint name="${prefix}depth_module" type="fixed">
        <origin xyz="0.0275 0.066 -0.00305" rpy="3.14159265358979 3.14159265358979 0" />
        <parent link="${prefix}end_effector_link" />
        <child  link="${prefix}camera_depth_frame" />
      </joint>
      <link name="${prefix}camera_color_frame" />
      <joint name="${prefix}color_module" type="fixed">
        <origin xyz="0 0.05639 -0.00305" rpy="3.14159265358979 3.14159265358979 0" />
        <parent link="${prefix}end_effector_link" />
        <child  link="${prefix}camera_color_frame" />
      </joint>

      <!-- Simulated Vision Definition by Rishik -->
      <xacro:if value="${sim}">
        <!-- COLOUR CAMERA -->
        <link name="rishik_camera_link">
          <visual>
            <geometry>
                <box size="0.01 0.005 0.005"/>
            </geometry>
            <material name="red"/>
          </visual>
        </link>
        <joint name="rishik_camera_joint" type="fixed">
          <parent link="${prefix}end_effector_link"/>
          <child link="rishik_camera_link"/>
          <origin xyz="0 0.05639 -0.00305" rpy="${-pi/2} ${-pi/2} 0" />
        </joint>

        <link name="rishik_camera_link_optical"></link>
        <joint name="camera_optical_joint" type="fixed">
          <parent link="rishik_camera_link"/>
          <child link="rishik_camera_link_optical"/>
          <origin xyz="0 0 0" rpy="${-pi/2} 0 ${-pi/2}"/>
        </joint>

        <gazebo reference="rishik_camera_link">
          <material>Gazebo/Red</material>
          <sensor name="camera" type="camera">
            <pose> 0 0 0 0 0 0 </pose>
            <visualize>true</visualize>
            <update_rate>15</update_rate>
            <camera>
              <horizontal_fov>1.0821</horizontal_fov> <!-- FROM KINOVA MANUAL, pg 24 -->
              <image>
                <format>R8G8B8</format>
                <width>640</width>
                <height>480</height>
              </image>
              <clip>
                <near>0.03</near>
                <far>8.0</far>
              </clip>
              <noise>
                <type>gaussian</type>
                <mean>0.0</mean>
                <stddev>0.007</stddev>
              </noise>
            </camera>
            <plugin name="camera_controller" filename="libgazebo_ros_camera.so">
                <frameName>rishik_camera_link_optical</frameName>
                <cameraName>camera/color</cameraName>
                <imageTopicName>image_raw</imageTopicName>
                <cameraInfoTopicName>camera_info</cameraInfoTopicName>
            </plugin>
          </sensor>
        </gazebo>

        <!-- DEPTH CAMERA -->
        <link name="rishik_dcamera_link">
          <visual>
            <geometry>
                <box size="0.01 0.005 0.005"/>
            </geometry>
            <material name="blue"/>
          </visual>
        </link>
        <joint name="rishik_dcamera_joint" type="fixed">
          <parent link="${prefix}end_effector_link"/>
          <child link="rishik_dcamera_link"/>
          <origin xyz="0 0.05639 -0.00305" rpy="${-pi/2} ${-pi/2} 0" />
        </joint>

        <link name="rishik_dcamera_link_optical"></link>
        <joint name="dcamera_optical_joint" type="fixed">
          <parent link="rishik_dcamera_link"/>
          <child link="rishik_dcamera_link_optical"/>
          <origin xyz="0 0 0" rpy="${-pi/2} 0 ${-pi/2}"/>
        </joint>

        <gazebo reference="rishik_dcamera_link">
          <material>Gazebo/Blue</material>
          <sensor name="depth_camera" type="depth">
            <always_on>1</always_on>
            <visualize>true</visualize>
            <update_rate>15</update_rate>
            <pose> 0 0 0 0 0 0 </pose>
            <camera>
              <horizontal_fov>1.29154</horizontal_fov> <!-- FROM KINOVA MANUAL, pg 25 -->
              <image>
                <format>R8G8B8</format>
                <width>480</width>
                <height>270</height>
              </image>
              <clip>
                <near>0.18</near> <!-- FROM KINOVA MANUAL, pg 25 -->
                <far>1.5</far> <!-- EXPERIMENTAL ESTIMATE -->
              </clip>
              <noise>
                <type>gaussian</type>
                <mean>0.0</mean>
                <stddev>0.007</stddev>
              </noise>
            </camera>
            <plugin name="kinect" filename="libgazebo_ros_openni_kinect.so">
              <frameName>rishik_dcamera_link/rishik_dcamera_link_optical</frameName>
              <cameraName>camera/depth</cameraName>
              <imageTopicName>rgb_image</imageTopicName>
              <depthImageTopicName>image_raw</depthImageTopicName>
              <depthImageCameraInfoTopicName>camera_info</depthImageCameraInfoTopicName>
              <pointCloudTopicName>points</pointCloudTopicName>
              <pointCloudCutoff>0.18</pointCloudCutoff>
              <pointCloudCutoffMax>1.5</pointCloudCutoffMax>
              <focalLength>0.0</focalLength>
              <alwaysOn>true</alwaysOn>
              <updateRate>0</updateRate>
              <!-- <CxPrime>0</CxPrime> -->
              <!-- <distortionK1>0.00000001</distortionK1>
              <distortionK2>0.00000001</distortionK2>
              <distortionK3>0.00000001</distortionK3>
              <distortionT1>0.00000001</distortionT1>
              <distortionT2>0.00000001</distortionT2> -->
            </plugin>
          </sensor>
        </gazebo>
      </xacro:if>
      
    </xacro:if>
  </xacro:macro>
</robot>
